Workbook

Sheet ESTOQUE
J2: Data Inicial | K2: 44890
J3: Data Final | K3: 46752
K5: Ultima atualização em 10/04/2026
C6: SKU | D6: Nome | E6: Estoque Inicial | F6: Entrada | G6: Saída | H6: Estoque Final | I6: Valor | K6: Insumo | L6: Nível | N6: Classificação
C7: 10060088 | D7: =VLOOKUP(C7,'Cadastro Produtos (kiwkiw)'!C:E,3,0) -> Anel Drop Banho Ouro | E7: =SUMIFS(DETALHADO!G:G,DETALHADO!D:D,"<"&ESTOQUE!$K$2,DETALHADO!E:E,ESTOQUE!$C7) -> 0 | F7: =SUMIFS(DETALHADO!G:G,DETALHADO!D:D,"<="&ESTOQUE!$K$3,DETALHADO!D:D,">="&ESTOQUE!$K$2,DETALHADO!E:E,ESTOQUE!$C7,DETALHADO!C:C,ESTOQUE!F$6) -> 19 | G7: =-SUMIFS(DETALHADO!G:G,DETALHADO!D:D,"<="&ESTOQUE!$K$3,DETALHADO!D:D,">="&ESTOQUE!$K$2,DETALHADO!E:E,ESTOQUE!$C7,DETALHADO!C:C,ESTOQUE!G$6) -> 12 | H7: =+E7+F7-G7 -> 7 | I7: =+H7*VLOOKUP(C7,'Cadastro Produtos (kiwkiw)'!C:F,4,0) -> 0 | K7: CAIXA | L7: ALTO | N7: Alto: acima de 600 unidades (aprox.)
C8: 10010088 | D8: =VLOOKUP(C8,'Cadastro Produtos (kiwkiw)'!C:E,3,0) -> Anel Duplo Banho Ouro | E8: =SUMIFS(DETALHADO!G:G,DETALHADO!D:D,"<"&ESTOQUE!$K$2,DETALHADO!E:E,ESTOQUE!$C8) -> 0 | F8: =SUMIFS(DETALHADO!G:G,DETALHADO!D:D,"<="&ESTOQUE!$K$3,DETALHADO!D:D,">="&ESTOQUE!$K$2,DETALHADO!E:E,ESTOQUE!$C8,DETALHADO!C:C,ESTOQUE!F$6) -> 18 | G8: =-SUMIFS(DETALHADO!G:G,DETALHADO!D:D,"<="&ESTOQUE!$K$3,DETALHADO!D:D,">="&ESTOQUE!$K$2,DETALHADO!E:E,ESTOQUE!$C8,DETALHADO!C:C,ESTOQUE!G$6) -> 18 | H8: =+E8+F8-G8 -> 0 | I8: =+H8*VLOOKUP(C8,'Cadastro Produtos (kiwkiw)'!C:F,4,0) -> 0 | K8: CARD | L8: ALTO | N8: Médio: de 300 a 600 uni (aprox.)
C9: 10020088 | D9: =VLOOKUP(C9,'Cadastro Produtos (kiwkiw)'!C:E,3,0) -> Anel Etta Banho Ouro | E9: =SUMIFS(DETALHADO!G:G,DETALHADO!D:D,"<"&ESTOQUE!$K$2,DETALHADO!E:E,ESTOQUE!$C9) -> 0 | F9: =SUMIFS(DETALHADO!G:G,DETALHADO!D:D,"<="&ESTOQUE!$K$3,DETALHADO!D:D,">="&ESTOQUE!$K$2,DETALHADO!E:E,ESTOQUE!$C9,DETALHADO!C:C,ESTOQUE!F$6) -> 22 | G9: =-SUMIFS(DETALHADO!G:G,DETALHADO!D:D,"<="&ESTOQUE!$K$3,DETALHADO!D:D,">="&ESTOQUE!$K$2,DETALHADO!E:E,ESTOQUE!$C9,DETALHADO!C:C,ESTOQUE!G$6) -> 22 | H9: =+E9+F9-G9 -> 0 | I9: =+H9*VLOOKUP(C9,'Cadastro Produtos (kiwkiw)'!C:F,4,0) -> 0 | K9: ESSENCIA DE CAIXA | L9: MÉDIO | N9: Baixo: até 300 unidades (aprox.)
C10: 10050088 | D10: =VLOOKUP(C10,'Cadastro Produtos (kiwkiw)'!C:E,3,0) -> Anel No Banho Ouro | E10: =SUMIFS(DETALHADO!G:G,DETALHADO!D:D,"<"&ESTOQUE!$K$2,DETALHADO!E:E,ESTOQUE!$C10) -> 0 | F10: =SUMIFS(DETALHADO!G:G,DETALHADO!D:D,"<="&ESTOQUE!$K$3,DETALHADO!D:D,">="&ESTOQUE!$K$2,DETALHADO!E:E,ESTOQUE!$C10,DETALHADO!C:C,ESTOQUE!F$6) -> 19 | G10: =-SUMIFS(DETALHADO!G:G,DETALHADO!D:D,"<="&ESTOQUE!$K$3,DETALHADO!D:D,">="&ESTOQUE!$K$2,DETALHADO!E:E,ESTOQUE!$C10,DETALHADO!C:C,ESTOQUE!G$6) -> 4 | H10: =+E10+F10-G10 -> 15 | I10: =+H10*VLOOKUP(C10,'Cadastro Produtos (kiwkiw)'!C:F,4,0) -> 0 | K10: SAQUINHO | L10: ALTO
C11: 10040088 | D11: =VLOOKUP(C11,'Cadastro Produtos (kiwkiw)'!C:E,3,0) -> Anel Roll Banho Ouro | E11: =SUMIFS(DETALHADO!G:G,DETALHADO!D:D,"<"&ESTOQUE!$K$2,DETALHADO!E:E,ESTOQUE!$C11) -> 0 | F11: =SUMIFS(DETALHADO!G:G,DETALHADO!D:D,"<="&ESTOQUE!$K$3,DETALHADO!D:D,">="&ESTOQUE!$K$2,DETALHADO!E:E,ESTOQUE!$C11,DETALHADO!C:C,ESTOQUE!F$6) -> 19 | G11: =-SUMIFS(DETALHADO!G:G,DETALHADO!D:D,"<="&ESTOQUE!$K$3,DETALHADO!D:D,">="&ESTOQUE!$K$2,DETALHADO!E:E,ESTOQUE!$C11,DETALHADO!C:C,ESTOQUE!G$6) -> 6 | H11: =+E11+F11-G11 -> 13 | I11: =+H11*VLOOKUP(C11,'Cadastro Produtos (kiwkiw)'!C:F,4,0) -> 0
C12: 10030088 | D12: =VLOOKUP(C12,'Cadastro Produtos (kiwkiw)'!C:E,3,0) -> Anel Zig Ajustavel Banho Ouro | E12: =SUMIFS(DETALHADO!G:G,DETALHADO!D:D,"<"&ESTOQUE!$K$2,DETALHADO!E:E,ESTOQUE!$C12) -> 0 | F12: =SUMIFS(DETALHADO!G:G,DETALHADO!D:D,"<="&ESTOQUE!$K$3,DETALHADO!D:D,">="&ESTOQUE!$K$2,DETALHADO!E:E,ESTOQUE!$C12,DETALHADO!C:C,ESTOQUE!F$6) -> 8 | G12: =-SUMIFS(DETALHADO!G:G,DETALHADO!D:D,"<="&ESTOQUE!$K$3,DETALHADO!D:D,">="&ESTOQUE!$K$2,DETALHADO!E:E,ESTOQUE!$C12,DETALHADO!C:C,ESTOQUE!G$6) -> 8 | H12: =+E12+F12-G12 -> 0 | I12: =+H12*VLOOKUP(C12,'Cadastro Produtos (kiwkiw)'!C:F,4,0) -> 0
C13: 20030088 | D13: =VLOOKUP(C13,'Cadastro Produtos (kiwkiw)'!C:E,3,0) -> Argola Amy Banho Ouro | E13: =SUMIFS(DETALHADO!G:G,DETALHADO!D:D,"<"&ESTOQUE!$K$2,DETALHADO!E:E,ESTOQUE!$C13) -> 0 | F13: =SUMIFS(DETALHADO!G:G,DETALHADO!D:D,"<="&ESTOQUE!$K$3,DETALHADO!D:D,">="&ESTOQUE!$K$2,DETALHADO!E:E,ESTOQUE!$C13,DETALHADO!C:C,ESTOQUE!F$6) -> 12 | G13: =-SUMIFS(DETALHADO!G:G,DETALHADO!D:D,"<="&ESTOQUE!$K$3,DETALHADO!D:D,">="&ESTOQUE!$K$2,DETALHADO!E:E,ESTOQUE!$C13,DETALHADO!C:C,ESTOQUE!G$6) -> 12 | H13: =+E13+F13-G13 -> 0 | I13: =+H13*VLOOKUP(C13,'Cadastro Produtos (kiwkiw)'!C:F,4,0) -> 0
C14: 20010088 | D14: =VLOOKUP(C14,'Cadastro Produtos (kiwkiw)'!C:E,3,0) -> Argola Bold Grande Banho Ouro | E14: =SUMIFS(DETALHADO!G:G,DETALHADO!D:D,"<"&ESTOQUE!$K$2,DETALHADO!E:E,ESTOQUE!$C14) -> 0 | F14: =SUMIFS(DETALHADO!G:G,DETALHADO!D:D,"<="&ESTOQUE!$K$3,DETALHADO!D:D,">="&ESTOQUE!$K$2,DETALHADO!E:E,ESTOQUE!$C14,DETALHADO!C:C,ESTOQUE!F$6) -> 13 | G14: =-SUMIFS(DETALHADO!G:G,DETALHADO!D:D,"<="&ESTOQUE!$K$3,DETALHADO!D:D,">="&ESTOQUE!$K$2,DETALHADO!E:E,ESTOQUE!$C14,DETALHADO!C:C,ESTOQUE!G$6) -> 13 | H14: =+E14+F14-G14 -> 0 | I14: =+H14*VLOOKUP(C14,'Cadastro Produtos (kiwkiw)'!C:F,4,0) -> 0
C15: 20020088 | D15: =VLOOKUP(C15,'Cadastro Produtos (kiwkiw)'!C:E,3,0) -> Argola Bold Pequena Banho Ouro | E15: =SUMIFS(DETALHADO!G:G,DETALHADO!D:D,"<"&ESTOQUE!$K$2,DETALHADO!E:E,ESTOQUE!$C15) -> 0 | F15: =SUMIFS(DETALHADO!G:G,DETALHADO!D:D,"<="&ESTOQUE!$K$3,DETALHADO!D:D,">="&ESTOQUE!$K$2,DETALHADO!E:E,ESTOQUE!$C15,DETALHADO!C:C,ESTOQUE!F$6) -> 17 | G15: =-SUMIFS(DETALHADO!G:G,DETALHADO!D:D,"<="&ESTOQUE!$K$3,DETALHADO!D:D,">="&ESTOQUE!$K$2,DETALHADO!E:E,ESTOQUE!$C15,DETALHADO!C:C,ESTOQUE!G$6) -> 17 | H15: =+E15+F15-G15 -> 0 | I15: =+H15*VLOOKUP(C15,'Cadastro Produtos (kiwkiw)'!C:F,4,0) -> 0
C16: 20130088 | D16: =VLOOKUP(C16,'Cadastro Produtos (kiwkiw)'!C:E,3,0) -> Argola Classy Banho Ouro | E16: =SUMIFS(DETALHADO!G:G,DETALHADO!D:D,"<"&ESTOQUE!$K$2,DETALHADO!E:E,ESTOQUE!$C16) -> 0 | F16: =SUMIFS(DETALHADO!G:G,DETALHADO!D:D,"<="&ESTOQUE!$K$3,DETALHADO!D:D,">="&ESTOQUE!$K$2,DETALHADO!E:E,ESTOQUE!$C16,DETALHADO!C:C,ESTOQUE!F$6) -> 62 | G16: =-SUMIFS(DETALHADO!G:G,DETALHADO!D:D,"<="&ESTOQUE!$K$3,DETALHADO!D:D,">="&ESTOQUE!$K$2,DETALHADO!E:E,ESTOQUE!$C16,DETALHADO!C:C,ESTOQUE!G$6) -> 40 | H16: =+E16+F16-G16 -> 22 | I16: =+H16*VLOOKUP(C16,'Cadastro Produtos (kiwkiw)'!C:F,4,0) -> 0
C17: 20140099 | D17: =VLOOKUP(C17,'Cadastro Produtos (kiwkiw)'!C:E,3,0) -> Argola Classy Prateada | E17: =SUMIFS(DETALHADO!G:G,DETALHADO!D:D,"<"&ESTOQUE!$K$2,DETALHADO!E:E,ESTOQUE!$C17) -> 0 | F17: =SUMIFS(DETALHADO!G:G,DETALHADO!D:D,"<="&ESTOQUE!$K$3,DETALHADO!D:D,">="&ESTOQUE!$K$2,DETALHADO!E:E,ESTOQUE!$C17,DETALHADO!C:C,ESTOQUE!F$6) -> 36 | G17: =-SUMIFS(DETALHADO!G:G,DETALHADO!D:D,"<="&ESTOQUE!$K$3,DETALHADO!D:D,">="&ESTOQUE!$K$2,DETALHADO!E:E,ESTOQUE!$C17,DETALHADO!C:C,ESTOQUE!G$6) -> 25 | H17: =+E17+F17-G17 -> 11 | I17: =+H17*VLOOKUP(C17,'Cadastro Produtos (kiwkiw)'!C:F,4,0) -> 0
C18: 20910088 | D18: =VLOOKUP(C18,'Cadastro Produtos (kiwkiw)'!C:E,3,0) -> Argola Click Croissant Banho Ouro | E18: =SUMIFS(DETALHADO!G:G,DETALHADO!D:D,"<"&ESTOQUE!$K$2,DETALHADO!E:E,ESTOQUE!$C18) -> 0 | F18: =SUMIFS(DETALHADO!G:G,DETALHADO!D:D,"<="&ESTOQUE!$K$3,DETALHADO!D:D,">="&ESTOQUE!$K$2,DETALHADO!E:E,ESTOQUE!$C18,DETALHADO!C:C,ESTOQUE!F$6) -> 20 | G18: =-SUMIFS(DETALHADO!G:G,DETALHADO!D:D,"<="&ESTOQUE!$K$3,DETALHADO!D:D,">="&ESTOQUE!$K$2,DETALHADO!E:E,ESTOQUE!$C18,DETALHADO!C:C,ESTOQUE!G$6) -> 5 | H18: =+E18+F18-G18 -> 15 | I18: =+H18*VLOOKUP(C18,'Cadastro Produtos (kiwkiw)'!C:F,4,0) -> 0
C19: 20070088 | D19: =VLOOKUP(C19,'Cadastro Produtos (kiwkiw)'!C:E,3,0) -> Argola Click Diamond Banho Ouro | E19: =SUMIFS(DETALHADO!G:G,DETALHADO!D:D,"<"&ESTOQUE!$K$2,DETALHADO!E:E,ESTOQUE!$C19) -> 0 | F19: =SUMIFS(DETALHADO!G:G,DETALHADO!D:D,"<="&ESTOQUE!$K$3,DETALHADO!D:D,">="&ESTOQUE!$K$2,DETALHADO!E:E,ESTOQUE!$C19,DETALHADO!C:C,ESTOQUE!F$6) -> 50 | G19: =-SUMIFS(DETALHADO!G:G,DETALHADO!D:D,"<="&ESTOQUE!$K$3,DETALHADO!D:D,">="&ESTOQUE!$K$2,DETALHADO!E:E,ESTOQUE!$C19,DETALHADO!C:C,ESTOQUE!G$6) -> 25 | H19: =+E19+F19-G19 -> 25 | I19: =+H19*VLOOKUP(C19,'Cadastro Produtos (kiwkiw)'!C:F,4,0) -> 0
C20: 20040088 | D20: =VLOOKUP(C20,'Cadastro Produtos (kiwkiw)'!C:E,3,0) -> Argola Click Grande Banho Ouro | E20: =SUMIFS(DETALHADO!G:G,DETALHADO!D:D,"<"&ESTOQUE!$K$2,DETALHADO!E:E,ESTOQUE!$C20) -> 0 | F20: =SUMIFS(DETALHADO!G:G,DETALHADO!D:D,"<="&ESTOQUE!$K$3,DETALHADO!D:D,">="&ESTOQUE!$K$2,DETALHADO!E:E,ESTOQUE!$C20,DETALHADO!C:C,ESTOQUE!F$6) -> 41 | G20: =-SUMIFS(DETALHADO!G:G,DETALHADO!D:D,"<="&ESTOQUE!$K$3,DETALHADO!D:D,">="&ESTOQUE!$K$2,DETALHADO!E:E,ESTOQUE!$C20,DETALHADO!C:C,ESTOQUE!G$6) -> 39 | H20: =+E20+F20-G20 -> 2 | I20: =+H20*VLOOKUP(C20,'Cadastro Produtos (kiwkiw)'!C:F,4,0) -> 0
C21: 20050088 | D21: =VLOOKUP(C21,'Cadastro Produtos (kiwkiw)'!C:E,3,0) -> Argola Click Media Banho Ouro | E21: =SUMIFS(DETALHADO!G:G,DETALHADO!D:D,"<"&ESTOQUE!$K$2,DETALHADO!E:E,ESTOQUE!$C21) -> 0 | F21: =SUMIFS(DETALHADO!G:G,DETALHADO!D:D,"<="&ESTOQUE!$K$3,DETALHADO!D:D,">="&ESTOQUE!$K$2,DETALHADO!E:E,ESTOQUE!$C21,DETALHADO!C:C,ESTOQUE!F$6) -> 46 | G21: =-SUMIFS(DETALHADO!G:G,DETALHADO!D:D,"<="&ESTOQUE!$K$3,DETALHADO!D:D,">="&ESTOQUE!$K$2,DETALHADO!E:E,ESTOQUE!$C21,DETALHADO!C:C,ESTOQUE!G$6) -> 34 | H21: =+E21+F21-G21 -> 12 | I21: =+H21*VLOOKUP(C21,'Cadastro Produtos (kiwkiw)'!C:F,4,0) -> 0
C22: 20060088 | D22: =VLOOKUP(C22,'Cadastro Produtos (kiwkiw)'!C:E,3,0) -> Argola Click Pequena Banho Ouro | E22: =SUMIFS(DETALHADO!G:G,DETALHADO!D:D,"<"&ESTOQUE!$K$2,DETALHADO!E:E,ESTOQUE!$C22) -> 0 | F22: =SUMIFS(DETALHADO!G:G,DETALHADO!D:D,"<="&ESTOQUE!$K$3,DETALHADO!D:D,">="&ESTOQUE!$K$2,DETALHADO!E:E,ESTOQUE!$C22,DETALHADO!C:C,ESTOQUE!F$6) -> 51 | G22: =-SUMIFS(DETALHADO!G:G,DETALHADO!D:D,"<="&ESTOQUE!$K$3,DETALHADO!D:D,">="&ESTOQUE!$K$2,DETALHADO!E:E,ESTOQUE!$C22,DETALHADO!C:C,ESTOQUE!G$6) -> 32 | H22: =+E22+F22-G22 -> 19 | I22: =+H22*VLOOKUP(C22,'Cadastro Produtos (kiwkiw)'!C:F,4,0) -> 0
... C198: 40210088 | D198: =VLOOKUP(C198,'Cadastro Produtos (kiwkiw)'!C:E,3,0) -> Pulseira Torcida Banho Ouro | E198: =SUMIFS(DETALHADO!G:G,DETALHADO!D:D,"<"&ESTOQUE!$K$2,DETALHADO!E:E,ESTOQUE!$C198) -> 0 | F198: =SUMIFS(DETALHADO!G:G,DETALHADO!D:D,"<="&ESTOQUE!$K$3,DETALHADO!D:D,">="&ESTOQUE!$K$2,DETALHADO!E:E,ESTOQUE!$C198,DETALHADO!C:C,ESTOQUE!F$6) -> 19 | G198: =-SUMIFS(DETALHADO!G:G,DETALHADO!D:D,"<="&ESTOQUE!$K$3,DETALHADO!D:D,">="&ESTOQUE!$K$2,DETALHADO!E:E,ESTOQUE!$C198,DETALHADO!C:C,ESTOQUE!G$6) -> 9 | H198: =+E198+F198-G198 -> 10 | I198: =+H198*VLOOKUP(C198,'Cadastro Produtos (kiwkiw)'!C:F,4,0) -> 0

Sheet DETALHADO
P1: Cubagem
A2: Cliente | B2: Log | C2: Tipo | D2: Data | E2: SKU | F2: Quantidade | G2: Ajuste | H2: Nome | I2: Observação | K2: Andar | L2: Zona | M2: Bloco | N2: Pavimento | O2: Posição | P2: Largura | Q2: Profundidade | R2: Altura | S2: Volume | V2: cod. caixa | W2: L | X2: P | Y2: A | Z2: preço | AB2: #NF
B3: 45476.681 | C3: Entrada | D3: 45476 | E3: 10010088 | F3: 17 | G3: =IF(C3="Entrada",F3,-F3) -> 17 | H3: =VLOOKUP(E3,'Cadastro Produtos (kiwkiw)'!C:E,3,0) -> Anel Duplo Banho Ouro | AB3: 3047
C4: Entrada | D4: 45476 | E4: 10020088 | F4: 22 | G4: =IF(C4="Entrada",F4,-F4) -> 22 | H4: =VLOOKUP(E4,'Cadastro Produtos (kiwkiw)'!C:E,3,0) -> Anel Etta Banho Ouro | AB4: 3047
C5: Entrada | D5: 45476 | E5: 10030088 | F5: 7 | G5: =IF(C5="Entrada",F5,-F5) -> 7 | H5: =VLOOKUP(E5,'Cadastro Produtos (kiwkiw)'!C:E,3,0) -> Anel Zig Ajustavel Banho Ouro | AB5: 3047
C6: Entrada | D6: 45476 | E6: 20010088 | F6: 12 | G6: =IF(C6="Entrada",F6,-F6) -> 12 | H6: =VLOOKUP(E6,'Cadastro Produtos (kiwkiw)'!C:E,3,0) -> Argola Bold Grande Banho Ouro | AB6: 3047
C7: Entrada | D7: 45476 | E7: 20020088 | F7: 17 | G7: =IF(C7="Entrada",F7,-F7) -> 17 | H7: =VLOOKUP(E7,'Cadastro Produtos (kiwkiw)'!C:E,3,0) -> Argola Bold Pequena Banho Ouro | I7: Recebemos 17 unidades e não 16 conforme NF | AB7: 3047
C8: Entrada | D8: 45476 | E8: 20030088 | F8: 11 | G8: =IF(C8="Entrada",F8,-F8) -> 11 | H8: =VLOOKUP(E8,'Cadastro Produtos (kiwkiw)'!C:E,3,0) -> Argola Amy Banho Ouro | AB8: 3047
C9: Entrada | D9: 45476 | E9: 20040088 | F9: 12 | G9: =IF(C9="Entrada",F9,-F9) -> 12 | H9: =VLOOKUP(E9,'Cadastro Produtos (kiwkiw)'!C:E,3,0) -> Argola Click Grande Banho Ouro | AB9: 3047
C10: Entrada | D10: 45476 | E10: 20050088 | F10: 12 | G10: =IF(C10="Entrada",F10,-F10) -> 12 | H10: =VLOOKUP(E10,'Cadastro Produtos (kiwkiw)'!C:E,3,0) -> Argola Click Media Banho Ouro | AB10: 3047
C11: Entrada | D11: 45476 | E11: 20060088 | F11: 19 | G11: =IF(C11="Entrada",F11,-F11) -> 19 | H11: =VLOOKUP(E11,'Cadastro Produtos (kiwkiw)'!C:E,3,0) -> Argola Click Pequena Banho Ouro | AB11: 3047
C12: Entrada | D12: 45476 | E12: 20070088 | F12: 19 | G12: =IF(C12="Entrada",F12,-F12) -> 19 | H12: =VLOOKUP(E12,'Cadastro Produtos (kiwkiw)'!C:E,3,0) -> Argola Click Diamond Banho Ouro | AB12: 3047
C13: Entrada | D13: 45476 | E13: 20080088 | F13: 14 | G13: =IF(C13="Entrada",F13,-F13) -> 14 | H13: =VLOOKUP(E13,'Cadastro Produtos (kiwkiw)'!C:E,3,0) -> Argola Organica Banho Ouro | AB13: 3047
C14: Entrada | D14: 45476 | E14: 20090088 | F14: 25 | G14: =IF(C14="Entrada",F14,-F14) -> 25 | H14: =VLOOKUP(E14,'Cadastro Produtos (kiwkiw)'!C:E,3,0) -> Argola Reta Basic Banho Ouro | AB14: 3047
C15: Entrada | D15: 45476 | E15: 20100088 | F15: 29 | G15: =IF(C15="Entrada",F15,-F15) -> 29 | H15: =VLOOKUP(E15,'Cadastro Produtos (kiwkiw)'!C:E,3,0) -> Argola Redonda Basic Banho Ouro | AB15: 3047
C16: Entrada | D16: 45476 | E16: 20110088 | F16: 30 | G16: =IF(C16="Entrada",F16,-F16) -> 30 | H16: =VLOOKUP(E16,'Cadastro Produtos (kiwkiw)'!C:E,3,0) -> Argola Torcida Banho Ouro | AB16: 3047
C17: Entrada | D17: 45476 | E17: 20120088 | F17: 11 | G17: =IF(C17="Entrada",F17,-F17) -> 11 | H17: =VLOOKUP(E17,'Cadastro Produtos (kiwkiw)'!C:E,3,0) -> Argola Tripla Banho Ouro | AB17: 3047
C18: Entrada | D18: 45476 | E18: 20130088 | F18: 39 | G18: =IF(C18="Entrada",F18,-F18) -> 39 | H18: =VLOOKUP(E18,'Cadastro Produtos (kiwkiw)'!C:E,3,0) -> Argola Classy Banho Ouro | AB18: 3047
C19: Entrada | D19: 45476 | E19: 20140099 | F19: 20 | G19: =IF(C19="Entrada",F19,-F19) -> 20 | H19: =VLOOKUP(E19,'Cadastro Produtos (kiwkiw)'!C:E,3,0) -> Argola Classy Prateada | AB19: 3047
... C68: Entrada | D68: 45476 | E68: 20630088 | F68: 29 | G68: =IF(C68="Entrada",F68,-F68) -> 29 | H68: =VLOOKUP(E68,'Cadastro Produtos (kiwkiw)'!C:E,3,0) -> Piercing Fake Dots Banho Ouro | AB68: 3047
C69: Entrada | D69: 45476 | E69: 20640088 | F69: 30 | G69: =IF(C69="Entrada",F69,-F69) -> 30 | H69: =VLOOKUP(E69,'Cadastro Produtos (kiwkiw)'!C:E,3,0) -> Piercing Fake Minimal Banho Ouro | I69: Recebemos 30 unidades e não 29 conforme NF | AB69: 3047
C70: Entrada | D70: 45476 | E70: 20650088 | F70: 19 | G70: =IF(C70="Entrada",F70,-F70) -> 19 | H70: =VLOOKUP(E70,'Cadastro Produtos (kiwkiw)'!C:E,3,0) -> Piercing Fake Classy Banho Ouro | AB70: 3047
C71: Entrada | D71: 45476 | E71: 20660099 | F71: 9 | G71: =IF(C71="Entrada",F71,-F71) -> 9 | H71: =VLOOKUP(E71,'Cadastro Produtos (kiwkiw)'!C:E,3,0) -> Piercing Fake Classy Prateado | AB71: 3047
C72: Entrada | D72: 45476 | E72: 30010088 | F72: 26 | G72: =IF(C72="Entrada",F72,-F72) -> 26 | H72: =VLOOKUP(E72,'Cadastro Produtos (kiwkiw)'!C:E,3,0) -> Colar Dot Banho Ouro | AB72: 3047
C73: Entrada | D73: 45476 | E73: 30020099 | F73: 19 | G73: =IF(C73="Entrada",F73,-F73) -> 19 | H73: =VLOOKUP(E73,'Cadastro Produtos (kiwkiw)'!C:E,3,0) -> Colar Dot Prateado | AB73: 3047
C74: Entrada | D74: 45476 | E74: 30030088 | F74: 20 | G74: =IF(C74="Entrada",F74,-F74) -> 20 | H74: =VLOOKUP(E74,'Cadastro Produtos (kiwkiw)'!C:E,3,0) -> Colar Rosa dos Ventos Banho Ouro | AB74: 3047
C75: Entrada | D75: 45476 | E75: 30040088 | F75: 45 | G75: =IF(C75="Entrada",F75,-F75) -> 45 | H75: =VLOOKUP(E75,'Cadastro Produtos (kiwkiw)'!C:E,3,0) -> Colar Coracao Banho Ouro | AB75: 3047
C76: Entrada | D76: 45476 | E76: 30050099 | F76: 27 | G76: =IF(C76="Entrada",F76,-F76) -> 27 | H76: =VLOOKUP(E76,'Cadastro Produtos (kiwkiw)'!C:E,3,0) -> Colar Coracao Prateado | AB76: 3047
C77: Entrada | D77: 45476 | E77: 30060088 | F77: 25 | G77: =IF(C77="Entrada",F77,-F77) -> 25 | H77: =VLOOKUP(E77,'Cadastro Produtos (kiwkiw)'!C:E,3,0) -> Colar Duplo Dots Banho Ouro | AB77: 3047
C78: Entrada | D78: 45476 | E78: 30070099 | F78: 19 | G78: =IF(C78="Entrada",F78,-F78) -> 19 | H78: =VLOOKUP(E78,'Cadastro Produtos (kiwkiw)'!C:E,3,0) -> Colar Duplo Dots Prateado | AB78: 3047
C79: Entrada | D79: 45476 | E79: 30080088 | F79: 13 | G79: =IF(C79="Entrada",F79,-F79) -> 13 | H79: =VLOOKUP(E79,'Cadastro Produtos (kiwkiw)'!C:E,3,0) -> Colar Duplo Minimal Banho Ouro | AB79: 3047
C80: Entrada | D80: 45476 | E80: 30090099 | F80: 8 | G80: =IF(C80="Entrada",F80,-F80) -> 8 | H80: =VLOOKUP(E80,'Cadastro Produtos (kiwkiw)'!C:E,3,0) -> Colar Duplo Minimal Prateado | AB80: 3047
C81: Entrada | D81: 45476 | E81: 30100088 | F81: 11 | G81: =IF(C81="Entrada",F81,-F81) -> 11 | H81: =VLOOKUP(E81,'Cadastro Produtos (kiwkiw)'!C:E,3,0) -> Colar Longo Esfera Banho Ouro | AB81: 3047
... C113: Entrada | D113: 45476 | E113: 40120099 | F113: 26 | G113: =IF(C113="Entrada",F113,-F113) -> 26 | H113: =VLOOKUP(E113,'Cadastro Produtos (kiwkiw)'!C:E,3,0) -> Pulseira Snake Prateada | AB113: 3047
B114: 45496.788 | C114: Saída | D114: 45495 | E114: 30160088 | F114: 1 | G114: =IF(C114="Entrada",F114,-F114) -> -1 | H114: =VLOOKUP(E114,'Cadastro Produtos (kiwkiw)'!C:E,3,0) -> Colar Ivy Banho Ouro | AB114: 3051
C115: Saída | D115: 45495 | E115: 20030088 | F115: 1 | G115: =IF(C115="Entrada",F115,-F115) -> -1 | H115: =VLOOKUP(E115,'Cadastro Produtos (kiwkiw)'!C:E,3,0) -> Argola Amy Banho Ouro | AB115: 3051
C116: Saída | D116: 45495 | E116: 20320088 | F116: 1 | G116: =IF(C116="Entrada",F116,-F116) -> -1 | H116: =VLOOKUP(E116,'Cadastro Produtos (kiwkiw)'!C:E,3,0) -> Brinco Ivy Banho Ouro | AB116: 3051
C117: Saída | D117: 45495 | E117: 20010088 | F117: 1 | G117: =IF(C117="Entrada",F117,-F117) -> -1 | H117: =VLOOKUP(E117,'Cadastro Produtos (kiwkiw)'!C:E,3,0) -> Argola Bold Grande Banho Ouro | AB117: 3051
C118: Saída | D118: 45495 | E118: 20280088 | F118: 1 | G118: =IF(C118="Entrada",F118,-F118) -> -1 | H118: =VLOOKUP(E118,'Cadastro Produtos (kiwkiw)'!C:E,3,0) -> Brinco Elos Banho Ouro | AB118: 3051
C119: Saída | D119: 45495 | E119: 10010088 | F119: 1 | G119: =IF(C119="Entrada",F119,-F119) -> -1 | H119: =VLOOKUP(E119,'Cadastro Produtos (kiwkiw)'!C:E,3,0) -> Anel Duplo Banho Ouro | AB119: 3051
...

Sheet Cadastro Produtos (kiwkiw)
H1: KITs
B2: Cod. De barras | C2: SKU | D2: Cliente | E2: Nome | F2: Valor Unitário | G2: Caixa usada | H2: SKU 1 | I2: Quantidade | J2: SKU 2 | K2: Quantidade | L2: SKU 3 | M2: quantidade | N2: Obs
C3: 10060088 | D3: Hava Acessorios LTDA | E3: Anel Drop Banho Ouro
C4: 10010088 | D4: Hava Acessorios LTDA | E4: Anel Duplo Banho Ouro
C5: 10020088 | D5: Hava Acessorios LTDA | E5: Anel Etta Banho Ouro
C6: 10050088 | D6: Hava Acessorios LTDA | E6: Anel No Banho Ouro
C7: 10040088 | D7: Hava Acessorios LTDA | E7: Anel Roll Banho Ouro
C8: 10030088 | D8: Hava Acessorios LTDA | E8: Anel Zig Ajustavel Banho Ouro
C9: 20030088 | D9: Hava Acessorios LTDA | E9: Argola Amy Banho Ouro
C10: 20010088 | D10: Hava Acessorios LTDA | E10: Argola Bold Grande Banho Ouro
C11: 20020088 | D11: Hava Acessorios LTDA | E11: Argola Bold Pequena Banho Ouro
C12: 20130088 | D12: Hava Acessorios LTDA | E12: Argola Classy Banho Ouro
C13: 20140099 | D13: Hava Acessorios LTDA | E13: Argola Classy Prateada
C14: 20910088 | D14: Hava Acessorios LTDA | E14: Argola Click Croissant Banho Ouro
... C194: 40210088 | D194: Hava Acessorios LTDA | E194: Pulseira Torcida Banho Ouro
